Workbook

Sheet OpticalCapableSatellites
A1: Constellation Name | B1: Operator | C1: Satellite Name | D1: NORAD ID | E1: Launch Date | F1: Decay Date | G1: Status
A2: AETHER | B2: Kepler Communications | C2: AETHER-8 | D2: 67379 | E2: 46033 | F2: =IF(D2="","", IFNA(VLOOKUP(D2, SATCAT_DECAY!A:B, 2, FALSE), "")) | G2: =IF(D2="","", IF(F2<>"","DECAYED","ACTIVE")) -> ACTIVE
A3: AETHER | B3: Kepler Communications | C3: AETHER-12 | D3: 67383 | E3: 46033 | F3: =IF(D3="","", IFNA(VLOOKUP(D3, SATCAT_DECAY!A:B, 2, FALSE), "")) | G3: =IF(D3="","", IF(F3<>"","DECAYED","ACTIVE")) -> ACTIVE | I3: Total optical link capable satellites | J3: =COUNTA(D:D) -> 6156
A4: AETHER | B4: Kepler Communications | C4: AETHER-11 | D4: 67382 | E4: 46033 | F4: =IF(D4="","", IFNA(VLOOKUP(D4, SATCAT_DECAY!A:B, 2, FALSE), "")) | G4: =IF(D4="","", IF(F4<>"","DECAYED","ACTIVE")) -> ACTIVE | I4: Total Kepler Satellites | J4: =COUNTIF(B:B,"Kepler Communications") -> 12
A5: AETHER | B5: Kepler Communications | C5: AETHER-5 | D5: 67376 | E5: 46033 | F5: =IF(D5="","", IFNA(VLOOKUP(D5, SATCAT_DECAY!A:B, 2, FALSE), "")) | G5: =IF(D5="","", IF(F5<>"","DECAYED","ACTIVE")) -> ACTIVE | I5: Total Starlink v2 mini Satellites | J5: =COUNTIF(B:B,"SpaceX v2 mini") -> 5890
A6: AETHER | B6: Kepler Communications | C6: AETHER-9 | D6: 67380 | E6: 46033 | F6: =IF(D6="","", IFNA(VLOOKUP(D6, SATCAT_DECAY!A:B, 2, FALSE), "")) | G6: =IF(D6="","", IF(F6<>"","DECAYED","ACTIVE")) -> ACTIVE | I6: Total Space Development Agency Satellites | J6: =COUNTIF(B:B,"Space Development Agency") -> 69
A7: AETHER | B7: Kepler Communications | C7: AETHER-6 | D7: 67377 | E7: 46033 | F7: =IF(D7="","", IFNA(VLOOKUP(D7, SATCAT_DECAY!A:B, 2, FALSE), "")) | G7: =IF(D7="","", IF(F7<>"","DECAYED","ACTIVE")) -> ACTIVE
A8: AETHER | B8: Kepler Communications | C8: AETHER-4 | D8: 67375 | E8: 46033 | F8: =IF(D8="","", IFNA(VLOOKUP(D8, SATCAT_DECAY!A:B, 2, FALSE), "")) | G8: =IF(D8="","", IF(F8<>"","DECAYED","ACTIVE")) -> ACTIVE
A9: AETHER | B9: Kepler Communications | C9: AETHER-3 | D9: 67374 | E9: 46033 | F9: =IF(D9="","", IFNA(VLOOKUP(D9, SATCAT_DECAY!A:B, 2, FALSE), "")) | G9: =IF(D9="","", IF(F9<>"","DECAYED","ACTIVE")) -> ACTIVE
A10: AETHER | B10: Kepler Communications | C10: AETHER-7 | D10: 67378 | E10: 46033 | F10: =IF(D10="","", IFNA(VLOOKUP(D10, SATCAT_DECAY!A:B, 2, FALSE), "")) | G10: =IF(D10="","", IF(F10<>"","DECAYED","ACTIVE")) -> ACTIVE
A11: AETHER | B11: Kepler Communications | C11: AETHER-10 | D11: 67381 | E11: 46033 | F11: =IF(D11="","", IFNA(VLOOKUP(D11, SATCAT_DECAY!A:B, 2, FALSE), "")) | G11: =IF(D11="","", IF(F11<>"","DECAYED","ACTIVE")) -> ACTIVE
A12: AETHER | B12: Kepler Communications | C12: AETHER-1 | D12: 58281 | E12: 45241 | F12: =IF(D12="","", IFNA(VLOOKUP(D12, SATCAT_DECAY!A:B, 2, FALSE), "")) | G12: =IF(D12="","", IF(F12<>"","DECAYED","ACTIVE")) -> ACTIVE
A13: AETHER | B13: Kepler Communications | C13: AETHER-2 | D13: 58299 | E13: 45241 | F13: =IF(D13="","", IFNA(VLOOKUP(D13, SATCAT_DECAY!A:B, 2, FALSE), "")) | G13: =IF(D13="","", IF(F13<>"","DECAYED","ACTIVE")) -> ACTIVE
A14: {=IFERROR( INDEX('Starlink Launches'!$A:$A, MATCH($E14, 'Starlink Launches'!$B:$B, 0)), "" )} -> 6-2 | B14: SpaceX v2 mini | C14: STARLINK-30096 | D14: 56286 | E14: 45035 | F14: =IF(D14="","", IFNA(VLOOKUP(D14, SATCAT_DECAY!A:B, 2, FALSE), "")) -> 45057 | G14: =IF(D14="","", IF(F14<>"","DECAYED","ACTIVE")) -> DECAYED
A15: {=IFERROR( INDEX('Starlink Launches'!$A:$A, MATCH($E15, 'Starlink Launches'!$B:$B, 0)), "" )} -> 6-2 | B15: SpaceX v2 mini | C15: STARLINK-30107 | D15: 56287 | E15: 45035 | F15: =IF(D15="","", IFNA(VLOOKUP(D15, SATCAT_DECAY!A:B, 2, FALSE), "")) | G15: =IF(D15="","", IF(F15<>"","DECAYED","ACTIVE")) -> ACTIVE
A16: {=IFERROR( INDEX('Starlink Launches'!$A:$A, MATCH($E16, 'Starlink Launches'!$B:$B, 0)), "" )} -> 6-2 | B16: SpaceX v2 mini | C16: STARLINK-30106 | D16: 56288 | E16: 45035 | F16: =IF(D16="","", IFNA(VLOOKUP(D16, SATCAT_DECAY!A:B, 2, FALSE), "")) | G16: =IF(D16="","", IF(F16<>"","DECAYED","ACTIVE")) -> ACTIVE
A17: {=IFERROR( INDEX('Starlink Launches'!$A:$A, MATCH($E17, 'Starlink Launches'!$B:$B, 0)), "" )} -> 6-2 | B17: SpaceX v2 mini | C17: STARLINK-30095 | D17: 56289 | E17: 45035 | F17: =IF(D17="","", IFNA(VLOOKUP(D17, SATCAT_DECAY!A:B, 2, FALSE), "")) | G17: =IF(D17="","", IF(F17<>"","DECAYED","ACTIVE")) -> ACTIVE
A18: {=IFERROR( INDEX('Starlink Launches'!$A:$A, MATCH($E18, 'Starlink Launches'!$B:$B, 0)), "" )} -> 6-2 | B18: SpaceX v2 mini | C18: STARLINK-30103 | D18: 56290 | E18: 45035 | F18: =IF(D18="","", IFNA(VLOOKUP(D18, SATCAT_DECAY!A:B, 2, FALSE), "")) | G18: =IF(D18="","", IF(F18<>"","DECAYED","ACTIVE")) -> ACTIVE
A19: {=IFERROR( INDEX('Starlink Launches'!$A:$A, MATCH($E19, 'Starlink Launches'!$B:$B, 0)), "" )} -> 6-2 | B19: SpaceX v2 mini | C19: STARLINK-30113 | D19: 56291 | E19: 45035 | F19: =IF(D19="","", IFNA(VLOOKUP(D19, SATCAT_DECAY!A:B, 2, FALSE), "")) | G19: =IF(D19="","", IF(F19<>"","DECAYED","ACTIVE")) -> ACTIVE
A20: {=IFERROR( INDEX('Starlink Launches'!$A:$A, MATCH($E20, 'Starlink Launches'!$B:$B, 0)), "" )} -> 6-2 | B20: SpaceX v2 mini | C20: STARLINK-30098 | D20: 56292 | E20: 45035 | F20: =IF(D20="","", IFNA(VLOOKUP(D20, SATCAT_DECAY!A:B, 2, FALSE), "")) | G20: =IF(D20="","", IF(F20<>"","DECAYED","ACTIVE")) -> ACTIVE
A21: {=IFERROR( INDEX('Starlink Launches'!$A:$A, MATCH($E21, 'Starlink Launches'!$B:$B, 0)), "" )} -> 6-2 | B21: SpaceX v2 mini | C21: STARLINK-30090 | D21: 56293 | E21: 45035 | F21: =IF(D21="","", IFNA(VLOOKUP(D21, SATCAT_DECAY!A:B, 2, FALSE), "")) | G21: =IF(D21="","", IF(F21<>"","DECAYED","ACTIVE")) -> ACTIVE
A22: {=IFERROR( INDEX('Starlink Launches'!$A:$A, MATCH($E22, 'Starlink Launches'!$B:$B, 0)), "" )} -> 6-2 | B22: SpaceX v2 mini | C22: STARLINK-30049 | D22: 56294 | E22: 45035 | F22: =IF(D22="","", IFNA(VLOOKUP(D22, SATCAT_DECAY!A:B, 2, FALSE), "")) | G22: =IF(D22="","", IF(F22<>"","DECAYED","ACTIVE")) -> ACTIVE
A23: {=IFERROR( INDEX('Starlink Launches'!$A:$A, MATCH($E23, 'Starlink Launches'!$B:$B, 0)), "" )} -> 6-2 | B23: SpaceX v2 mini | C23: STARLINK-30083 | D23: 56295 | E23: 45035 | F23: =IF(D23="","", IFNA(VLOOKUP(D23, SATCAT_DECAY!A:B, 2, FALSE), "")) | G23: =IF(D23="","", IF(F23<>"","DECAYED","ACTIVE")) -> ACTIVE
A24: {=IFERROR( INDEX('Starlink Launches'!$A:$A, MATCH($E24, 'Starlink Launches'!$B:$B, 0)), "" )} -> 6-2 | B24: SpaceX v2 mini | C24: STARLINK-30089 | D24: 56296 | E24: 45035 | F24: =IF(D24="","", IFNA(VLOOKUP(D24, SATCAT_DECAY!A:B, 2, FALSE), "")) | G24: =IF(D24="","", IF(F24<>"","DECAYED","ACTIVE")) -> ACTIVE
A25: {=IFERROR( INDEX('Starlink Launches'!$A:$A, MATCH($E25, 'Starlink Launches'!$B:$B, 0)), "" )} -> 6-2 | B25: SpaceX v2 mini | C25: STARLINK-30086 | D25: 56297 | E25: 45035 | F25: =IF(D25="","", IFNA(VLOOKUP(D25, SATCAT_DECAY!A:B, 2, FALSE), "")) | G25: =IF(D25="","", IF(F25<>"","DECAYED","ACTIVE")) -> ACTIVE
... A2604: {=IFERROR( INDEX('Starlink Launches'!$A:$A, MATCH($E2604, 'Starlink Launches'!$B:$B, 0)), "" )} -> 7-11 | B2604: SpaceX v2 mini | C2604: STARLINK-31262 | D2604: 58847 | E2604: 45315 | F2604: =IF(D2604="","", IFNA(VLOOKUP(D2604, SATCAT_DECAY!A:B, 2, FALSE), "")) | G2604: =IF(D2604="","", IF(F2604<>"","DECAYED","ACTIVE")) -> ACTIVE
A2605: 7-12 | B2605: SpaceX v2 mini | C2605: STARLINK-31306 | D2605: 58876 | E2605: 45320 | F2605: =IF(D2605="","", IFNA(VLOOKUP(D2605, SATCAT_DECAY!A:B, 2, FALSE), "")) | G2605: =IF(D2605="","", IF(F2605<>"","DECAYED","ACTIVE")) -> ACTIVE
A2606: 7-12 | B2606: SpaceX v2 mini | C2606: STARLINK-31326 | D2606: 58877 | E2606: 45320 | F2606: =IF(D2606="","", IFNA(VLOOKUP(D2606, SATCAT_DECAY!A:B, 2, FALSE), "")) | G2606: =IF(D2606="","", IF(F2606<>"","DECAYED","ACTIVE")) -> ACTIVE
A2607: 7-12 | B2607: SpaceX v2 mini | C2607: STARLINK-31300 | D2607: 58878 | E2607: 45320 | F2607: =IF(D2607="","", IFNA(VLOOKUP(D2607, SATCAT_DECAY!A:B, 2, FALSE), "")) | G2607: =IF(D2607="","", IF(F2607<>"","DECAYED","ACTIVE")) -> ACTIVE
A2608: 7-12 | B2608: SpaceX v2 mini | C2608: STARLINK-31296 | D2608: 58879 | E2608: 45320 | F2608: =IF(D2608="","", IFNA(VLOOKUP(D2608, SATCAT_DECAY!A:B, 2, FALSE), "")) | G2608: =IF(D2608="","", IF(F2608<>"","DECAYED","ACTIVE")) -> ACTIVE
A2609: 7-12 | B2609: SpaceX v2 mini | C2609: STARLINK-31328 | D2609: 58880 | E2609: 45320 | F2609: =IF(D2609="","", IFNA(VLOOKUP(D2609, SATCAT_DECAY!A:B, 2, FALSE), "")) | G2609: =IF(D2609="","", IF(F2609<>"","DECAYED","ACTIVE")) -> ACTIVE
A2610: 7-12 | B2610: SpaceX v2 mini | C2610: STARLINK-31260 | D2610: 58881 | E2610: 45320 | F2610: =IF(D2610="","", IFNA(VLOOKUP(D2610, SATCAT_DECAY!A:B, 2, FALSE), "")) | G2610: =IF(D2610="","", IF(F2610<>"","DECAYED","ACTIVE")) -> ACTIVE
A2611: 7-12 | B2611: SpaceX v2 mini | C2611: STARLINK-31323 | D2611: 58882 | E2611: 45320 | F2611: =IF(D2611="","", IFNA(VLOOKUP(D2611, SATCAT_DECAY!A:B, 2, FALSE), "")) | G2611: =IF(D2611="","", IF(F2611<>"","DECAYED","ACTIVE")) -> ACTIVE
A2612: 7-12 | B2612: SpaceX v2 mini | C2612: STARLINK-31209 | D2612: 58883 | E2612: 45320 | F2612: =IF(D2612="","", IFNA(VLOOKUP(D2612, SATCAT_DECAY!A:B, 2, FALSE), "")) | G2612: =IF(D2612="","", IF(F2612<>"","DECAYED","ACTIVE")) -> ACTIVE
A2613: 7-12 | B2613: SpaceX v2 mini | C2613: STARLINK-31315 | D2613: 58884 | E2613: 45320 | F2613: =IF(D2613="","", IFNA(VLOOKUP(D2613, SATCAT_DECAY!A:B, 2, FALSE), "")) | G2613: =IF(D2613="","", IF(F2613<>"","DECAYED","ACTIVE")) -> ACTIVE
A2614: 7-12 | B2614: SpaceX v2 mini | C2614: STARLINK-31318 | D2614: 58885 | E2614: 45320 | F2614: =IF(D2614="","", IFNA(VLOOKUP(D2614, SATCAT_DECAY!A:B, 2, FALSE), "")) | G2614: =IF(D2614="","", IF(F2614<>"","DECAYED","ACTIVE")) -> ACTIVE
A2615: 7-12 | B2615: SpaceX v2 mini | C2615: STARLINK-31320 | D2615: 58886 | E2615: 45320 | F2615: =IF(D2615="","", IFNA(VLOOKUP(D2615, SATCAT_DECAY!A:B, 2, FALSE), "")) | G2615: =IF(D2615="","", IF(F2615<>"","DECAYED","ACTIVE")) -> ACTIVE
A2616: 7-12 | B2616: SpaceX v2 mini | C2616: STARLINK-31321 | D2616: 58887 | E2616: 45320 | F2616: =IF(D2616="","", IFNA(VLOOKUP(D2616, SATCAT_DECAY!A:B, 2, FALSE), "")) | G2616: =IF(D2616="","", IF(F2616<>"","DECAYED","ACTIVE")) -> ACTIVE
... A2626: 7-12 | B2626: SpaceX v2 mini | C2626: STARLINK-31190 | D2626: 58897 | E2626: 45320 | F2626: =IF(D2626="","", IFNA(VLOOKUP(D2626, SATCAT_DECAY!A:B, 2, FALSE), "")) | G2626: =IF(D2626="","", IF(F2626<>"","DECAYED","ACTIVE")) -> ACTIVE
A2627: {=IFERROR( INDEX('Starlink Launches'!$A:$A, MATCH($E2627, 'Starlink Launches'!$B:$B, 0)), "" )} -> 7-13 | B2627: SpaceX v2 mini | C2627: STARLINK-31317 | D2627: 58931 | E2627: 45332 | F2627: =IF(D2627="","", IFNA(VLOOKUP(D2627, SATCAT_DECAY!A:B, 2, FALSE), "")) | G2627: =IF(D2627="","", IF(F2627<>"","DECAYED","ACTIVE")) -> ACTIVE
...

Sheet Starlink Launches
A1: Group | B1: Launch Date | C1: Version | D1: Deployed | E1: Working | F1: Note | G1: Decayed Satellites
A2: 6-1 | B2: 44984 | C2: v2 mini | D2: 21 | E2: 12 | F2: Not working | G2: =D2-E2 -> 9
A3: 6-2 | B3: 45035 | C3: v2 mini | D3: 21 | E3: 20 | G3: =D3-E3 -> 1 | I3: Total Launches | J3: =COUNTA(A:A) -> 257
A4: 6-3 | B4: 45065 | C4: v2 mini | D4: 22 | E4: 21 | G4: =D4-E4 -> 1 | I4: Total Deployed | J4: =SUM(D:D) -> 6132
A5: 6-4 | B5: 45081 | C5: v2 mini | D5: 22 | E5: 19 | G5: =D5-E5 -> 3 | I5: Total Working | J5: =SUM(E:E) -> 6089 | K5: =J4-J5 -> 43
A6: 6-5 | B6: 45117 | C6: v2 mini | D6: 22 | E6: 22 | G6: =D6-E6 -> 0 | I6: Mult Launch Dates | J6: {=COUNTA(B2:B315) - COUNTA(UNIQUE(B2:B315))} -> 20
A7: 6-15 | B7: 45127 | C7: v2 mini | D7: 15 | E7: 15 | G7: =D7-E7 -> 0
A8: 6-6 | B8: 45131 | C8: v2 mini | D8: 22 | E8: 22 | G8: =D8-E8 -> 0 | I8: Earliest Launch Date | J8: =MIN(B:B) -> 44984
A9: 6-7 | B9: 45135 | C9: v2 mini | D9: 22 | E9: 20 | G9: =D9-E9 -> 2 | I9: Latest Launch Date | J9: =MAX(B:B) -> 46063
A10: 6-8 | B10: 45145 | C10: v2 mini | D10: 22 | E10: 22 | G10: =D10-E10 -> 0 | I10: Satellites Deployed / Day | J10: =J4/(J9-J8) -> 5.6830399
A11: 6-20 | B11: 45146 | C11: v2 mini | D11: 15 | E11: 15 | G11: =D11-E11 -> 0 | I11: Days / Launch | J11: =(J9-J8)/J3 -> 4.1984436
A12: 6-9 | B12: 45149 | C12: v2 mini | D12: 22 | E12: 21 | G12: =D12-E12 -> 1 | I12: Satellites / Launch | J12: =J4/J3 -> 23.859922
A13: 6-10 | B13: 45155 | C13: v2 mini | D13: 22 | E13: 22 | G13: =D13-E13 -> 0
A14: 6-11 | B14: 45165 | C14: v2 mini | D14: 22 | E14: 21 | G14: =D14-E14 -> 1
A15: 6-13 | B15: 45170 | C15: v2 mini | D15: 22 | E15: 22 | G15: =D15-E15 -> 0
A16: 6-12 | B16: 45173 | C16: v2 mini | D16: 21 | E16: 21 | G16: =D16-E16 -> 0
A17: 6-14 | B17: 45178 | C17: v2 mini | D17: 22 | E17: 22 | G17: =D17-E17 -> 0
A18: 6-16 | B18: 45185 | C18: v2 mini | D18: 22 | E18: 22 | G18: =D18-E18 -> 0
A19: 6-17 | B19: 45189 | C19: v2 mini | D19: 22 | E19: 22 | G19: =D19-E19 -> 0
A20: 6-18 | B20: 45193 | C20: v2 mini | D20: 22 | E20: 21 | G20: =D20-E20 -> 1
A21: 6-19 | B21: 45199 | C21: v2 mini | D21: 22 | E21: 22 | G21: =D21-E21 -> 0
A22: 6-21 | B22: 45204 | C22: v2 mini | D22: 22 | E22: 22 | G22: =D22-E22 -> 0
A23: 6-22 | B23: 45212 | C23: v2 mini | D23: 22 | E23: 22 | G23: =D23-E23 -> 0
A24: 6-23 | B24: 45217 | C24: v2 mini | D24: 22 | E24: 22 | G24: =D24-E24 -> 0
... A134: 9-2 | B134: 45467 | C134: v2 mini | D134: 20 | E134: 20 | G134: =D134-E134 -> 0
A135: 9-3 | B135: 45485 | C135: v2 mini | D135: 20 | E135: 0 | F135: Failed Launch | G135: =D135-E135 -> 20
A136: 9-4 | B136: 45501 | C136: v2 mini | D136: 21 | E136: 21 | G136: =D136-E136 -> 0
A137: 9-5 | B137: 45535 | C137: v2 mini | D137: 21 | E137: 21 | G137: =D137-E137 -> 0
A138: 9-6 | B138: 45548 | C138: v2 mini | D138: 21 | E138: 21 | G138: =D138-E138 -> 0
A139: 9-17 | B139: 45555 | C139: v2 mini | D139: 20 | E139: 20 | G139: =D139-E139 -> 0
A140: 9-8 | B140: 45560 | C140: v2 mini | D140: 20 | E140: 20 | G140: =D140-E140 -> 0
A141: 9-7 | B141: 45580 | C141: v2 mini | D141: 20 | E141: 20 | G141: =D141-E141 -> 0
A142: 9-9 | B142: 45595 | C142: v2 mini | D142: 20 | E142: 20 | G142: =D142-E142 -> 0
A143: 9-10 | B143: 45605 | C143: v2 mini | D143: 20 | E143: 20 | G143: =D143-E143 -> 0
A144: 9-11 | B144: 45610 | C144: v2 mini | D144: 20 | E144: 20 | G144: =D144-E144 -> 0
A145: 9-12 | B145: 45614 | C145: v2 mini | D145: 20 | E145: 20 | G145: =D145-E145 -> 0
A146: 9-13 | B146: 45620 | C146: v2 mini | D146: 20 | E146: 20 | G146: =D146-E146 -> 0
A147: 9-14 | B147: 45631 | C147: v2 mini | D147: 20 | E147: 20 | G147: =D147-E147 -> 0
... A225: 13-1 | B225: 45678 | C225: v2 mini | D225: 21 | E225: 21 | G225: =D225-E225 -> 0
A226: 13-4 | B226: 45869 | C226: v2 mini | D226: 19 | E226: 19 | F226: Not working | G226: =D226-E226 -> 0
...

Sheet Leo Launches
A1: Group | B1: Launch Date | C1: Version | D1: Deployed | E1: Working | F1: Note | G1: Decayed Satellites
A2: Protoflight | B2: 45205 | C2: Leo | D2: 2 | E2: 0 | G2: =D2-E2 -> 2
A3: KA-01 | B3: 45775 | C3: Leo | D3: 27 | E3: 27 | G3: =D3-E3 -> 0 | I3: Total Launches | J3: =COUNTA(A:A) -> 11
A4: KA-02 | B4: 45831 | C4: Leo | D4: 27 | E4: 27 | G4: =D4-E4 -> 0 | I4: Total Deployed | J4: =SUM(D:D) -> 182
A5: KF-01 | B5: 45854 | C5: Leo | D5: 24 | E5: 24 | G5: =D5-E5 -> 0 | I5: Total Working | J5: =SUM(E:E) -> 180 | K5: =J4-J5 -> 2
A6: KF-02 | B6: 45880 | C6: Leo | D6: 24 | E6: 24 | G6: =D6-E6 -> 0 | I6: Mult Launch Dates | J6: {=COUNTA(B2:B314) - COUNTA(UNIQUE(B2:B314))} -> 0
A7: KA-03 | B7: 45925 | C7: Leo | D7: 27 | E7: 27 | G7: =D7-E7 -> 0
A8: KF-03 | B8: 45944 | C8: Leo | D8: 24 | E8: 24 | G8: =D8-E8 -> 0 | I8: Earliest Launch Date | J8: =B2 -> 45205
A9: LA-04 | B9: 46007 | C9: Leo | D9: 27 | E9: 27 | G9: =D9-E9 -> 0 | I9: Latest Launch Date | J9: =B9 -> 46007
A10: LE-01 | B10: 46065 | G10: =D10-E10 -> 0 | I10: Satellites Deployed / Day | J10: =J4/(J9-J8) -> 0.22693267
A11: LV-01 | B11: 46082 | G11: =D11-E11 -> 0 | I11: Days / Launch | J11: =(J9-J8)/J3 -> 72.909091
G12: =D12-E12 -> 0 | I12: Satellites / Launch | J12: =J4/J3 -> 16.545455
G13: =D13-E13 -> 0
G225: =D225-E225 -> 0
G226: =D226-E226 -> 0
G227: =D227-E227 -> 0
G228: =D228-E228 -> 0
G229: =D229-E229 -> 0
G230: =D230-E230 -> 0
G231: =D231-E231 -> 0
G232: =D232-E232 -> 0
G233: =D233-E233 -> 0
G234: =D234-E234 -> 0
G235: =D235-E235 -> 0
... G314: =D314-E314 -> 0

Sheet SATCAT_DECAY
A1: NORAD_CAT_ID | B1: DECAY_DATE
A2: 44235 | B2: 44105
A3: 44236 | B3: 44052
A4: 44237 | B4: 44076
A5: 44238 | B5: 44858
A6: 44239 | B6: 44075
A7: 44240 | B7: 44296
A8: 44241 | B8: 44100
A9: 44242 | B9: 44064
A10: 44243 | B10: 44117
A11: 44244 | B11: 44117
A12: 44245 | B12: 44096
A13: 44246 | B13: 43881
... A62: 44713 | B62: 45567
A63: 44714
A64: 44715 | B64: 45709
A65: 44716 | B65: 45976
A66: 44717 | B66: 45997
A67: 44718
A68: 44719 | B68: 45901
A69: 44720 | B69: 45853
A70: 44721 | B70: 45934
A71: 44722 | B71: 44966
A72: 44723
A73: 44724
A74: 44725
A75: 44726 | B75: 45941
A76: 44727 | B76: 45136
A77: 44728 | B77: 44550
A78: 44729 | B78: 45379
A79: 44730 | B79: 44424
A80: 44731 | B80: 45191
A81: 44732 | B81: 45774
A82: 44733 | B82: 45702
A83: 44734 | B83: 45948
A84: 44735 | B84: 45919
A85: 44736
A86: 44737 | B86: 45742
A87: 44738 | B87: 45207
A88: 44739 | B88: 45180
...
